<?xml version="1.0"?>

<robot xmlns:xacro="http://ros.org/wiki/xacro" name="wheel">
  <xacro:property name="M_PI" value="3.1415926535897931"/>

  <!-- Wheel -->
  <xacro:macro name="wheel" params="wheel_prefix parent *joint_pose">
    <link name="${wheel_prefix}_wheel_link">
      <inertial>
        <mass value="1.0"/>
        <origin xyz="0 0 0" rpy="0 0 0"/>
        <inertia ixx="0.0046271" ixy="0" ixz="0" iyy="0.0081281" iyz="0" izz="0.0046271"/> <!-- wheel_radius=0.1275  |  wheel_length=0.0822 -->
      </inertial>
      <visual>
        <origin xyz="0 0 0" rpy="0 0 0"/>
        <geometry>
          <mesh filename="package://atlas80evo_description/meshes/atlas80evo/Wheel.STL"/>
        </geometry>
        <material name="grey"><!-- silver -->
          <color rgba="0.175 0.175 0.175 1"/><!-- 0.74 0.76 0.78 1 -->
        </material>
      </visual>
      <collision>
        <origin xyz="0 0 0" rpy="0 0 0"/>
        <geometry>
          <mesh filename="package://atlas80evo_description/meshes/atlas80evo/Wheel.STL"/>
        </geometry>
      </collision>
    </link>

    <gazebo reference="${wheel_prefix}_wheel_link">
      <material>Gazebo/Grey</material>
      <mu1 value="1.0"/>
      <mu2 value="1.0"/>
      <kp value="10000000.0"/>
      <kd value="1.0"/>
      <fdir1 value="1 0 0"/>
    </gazebo>

    <!-- Wheel Joint -->
    <joint name="${wheel_prefix}_wheel_joint" type="continuous">
      <parent link="${parent}"/>
      <child link="${wheel_prefix}_wheel_link"/>
      <xacro:insert_block name="joint_pose"/>
      <axis xyz="0 1 0"/>
      <limit effort="10000" velocity="1000"/>
      <joint_properties damping="1.0" friction="1.0"/>
    </joint>

    <transmission name="${wheel_prefix}_wheel_transmission">
      <type>transmission_interface/SimpleTransmission</type>
      <joint name="${wheel_prefix}_wheel_joint">
        <hardwareInterface>hardware_interface/VelocityJointInterface</hardwareInterface>
      </joint>
      <actuator name="${wheel_prefix}_wheel_motor">
        <hardwareInterface>hardware_interface/VelocityJointInterface</hardwareInterface>
        <mechanicalReduction>1</mechanicalReduction>
      </actuator>
    </transmission>

<!--    <gazebo>
      <plugin name="gazebo_ros_control" filename="libgazebo_ros_control.so">
-->
<!--        <robotNamespace>$(arg robot_namespace)</robotNamespace> -->
<!--        <robotSimType>gazebo_ros_control/DefaultRobotHWSim</robotSimType> -->
<!--        <legacyModeNS>true</legacyModeNS> -->
<!--        <controlPeriod>0.001</controlPeriod> -->
<!--      </plugin>
    </gazebo>
-->

  </xacro:macro>
</robot>
